#VRML_SIM R2020b utf8
WorldInfo {
  coordinateSystem "NUE"
  contactProperties [
    ContactProperties {
      coulombFriction [
        0.5
      ]
      forceDependentSlip [
        0.5
      ]
    }
  ]
}
Viewpoint {
  orientation -0.9127939853172378 0.368875188294906 0.17532323242819778 0.8966921066769121
  position 2.1928666042683713 10.702869153587695 7.656994161815878
}
TexturedBackground {
}
TexturedBackgroundLight {
}
RectangleArena {
  floorSize 8 7
  wallHeight 0.5
}
PottedTree {
  translation 2.5654620573991376 -0.0077452966465534345 0.7527284576554107
  rotation -6.045404267557882e-13 1 5.826310984607704e-15 0.00047613697986750576
  physics Physics {
    density 50
  }
}
PottedTree {
  translation 2.5861070689779515 -0.0077452966465534345 -1.2037046903101654
  rotation 4.940033807926041e-12 0.9999999999999999 1.527513714953261e-12 1.4326044797070877e-05
  name "potted tree(1)"
  physics Physics {
    density 50
  }
}
Toilet {
  translation 2.23956 0 2.08618
  rotation 0 1 0 -1.5707953071795862
}
WoodenBox {
  translation 0.8165372530019275 0.44215252076310385 -2.7348974187971886
  rotation 1.7798388983175797e-17 1 3.111354365706497e-16 -0.05206727688234307
  name "wooden box(5)"
  size 0.3 0.9 0.3
  mass 20
}
Desk {
  translation 0 0 -2.36
}
WoodenBox {
  translation 2.370347588513531 0.14215252076310383 -0.2038824183365867
  rotation 1.5267090650784883e-16 1 -1.553620191649644e-16 0.2073543462972509
  size 0.3 0.3 0.3
  mass 20
}
WoodenBox {
  translation -2.0521289563889034 0.29215252076310383 -2.5466362542521344
  rotation -1.6809535937105218e-16 1 6.969617489182188e-16 -0.04382917095357326
  name "wooden box(1)"
  size 0.3 0.6 0.3
  mass 20
}
WoodenBox {
  translation -1.2642749040865886 0.44215252076310385 -2.5145497724923467
  rotation 2.1180850005028036e-15 1 4.856981212224915e-16 -0.045014665838977785
  name "wooden box(4)"
  size 0.3 0.9 0.3
  mass 20
}
WoodenBox {
  translation -1.67417345170206 0.14215252076310386 1.6862114927485892
  rotation 3.4193054196008052e-15 1 -2.1019161949772509e-16 0.004381299953868817
  name "wooden box(2)"
  size 0.3 0.3 0.3
  mass 20
}
WoodenBox {
  translation 2.1233766045707267 0.14215252076310386 -2.4745434837069262
  rotation 7.117381835722473e-17 1 4.5601631442287705e-17 1.1035397314704913
  name "wooden box(3)"
  size 0.3 0.3 0.3
  mass 20
}
Robot {
  translation -1.0252412085350027 0.02980765522663778 0.29438431325690695
  rotation 0.00043723747383451285 -0.9999999022112611 -6.633897583316883e-05 0.8560197384114892
  children [
    Camera {
      translation 0 0.016 0.085
      rotation 0 1 0 3.14
      children [
        Transform {
          rotation 0 1 0 3.14
          children [
            Shape {
              appearance PBRAppearance {
                baseColor 0.5 0 1
                metalness 0
              }
              geometry Cone {
                bottomRadius 0.005
                height 0.01
              }
            }
          ]
        }
      ]
      fieldOfView 2
      width 256
      height 128
    }
    GPS {
    }
    Compass {
      translation -0.02 0.01 0
      children [
        Shape {
          appearance PBRAppearance {
            baseColor 0 0.2 1
            metalness 0
          }
          geometry Cylinder {
            height 0.005
            radius 0.01
          }
        }
      ]
    }
    Accelerometer {
      translation 0.02 0.01 0
      children [
        Shape {
          appearance PBRAppearance {
            baseColor 0 0.2 1
            metalness 0
          }
          geometry Cylinder {
            height 0.005
            radius 0.01
          }
        }
      ]
    }
    Gyro {
      translation 0 0.01 0.02
      children [
        Shape {
          appearance PBRAppearance {
            baseColor 1 0.1 0.1
            metalness 0
          }
          geometry Box {
            size 0.05 0.005 0.015
          }
        }
      ]
    }
    InertialUnit {
      translation 0 0.01 0.055
      children [
        Shape {
          appearance PBRAppearance {
            baseColor 1 0.1 0.1
            metalness 0
          }
          geometry Box {
            size 0.015 0.005 0.04
          }
        }
      ]
      name "imu"
    }
    DistanceSensor {
      translation 0.03 0 0.097
      rotation 0 1 0 -1.57
      children [
        Shape {
          appearance PBRAppearance {
            baseColor 0.2 1 1
            metalness 0
          }
          geometry Box {
            size 0.015 0.015 0.015
          }
        }
      ]
      name "ds_left"
    }
    DistanceSensor {
      translation -0.03 0 0.097
      rotation 0 1 0 -1.57
      children [
        Shape {
          appearance PBRAppearance {
            baseColor 0.2 1 1
            metalness 0
          }
          geometry Box {
            size 0.015 0.015 0.015
          }
        }
      ]
      name "ds_right"
    }
    DEF lidar Transform {
      translation 0 0.07 -0.04
      rotation 0 1 0 3.14
      children [
        Shape {
          appearance PBRAppearance {
            metalness 0
          }
          geometry Box {
            size 0.03 0.03 0.03
          }
        }
        DEF LIDAR Lidar {
          name "sick"
          model "sick_model"
          horizontalResolution 994
          fieldOfView 6.283
          verticalFieldOfView 0.5233
          numberOfLayers 16
          minRange 0.1
          maxRange 15
        }
      ]
    }
    DEF wheel1 HingeJoint {
      jointParameters HingeJointParameters {
        position 16890.203273175877
        anchor 0.06 0 0.08
      }
      device [
        RotationalMotor {
          name "wheel1"
          maxVelocity 30
        }
      ]
      endPoint Solid {
        translation 0.06000388540791468 4.214354313029338e-05 0.08001833506421194
        rotation -0.4268120388355862 0.4264734555878149 -0.7974659084775964 4.488756808809252
        children [
          DEF Wheel Shape {
            appearance PBRAppearance {
              baseColor 1 0.4 0.6
              metalness 0
            }
            geometry Cylinder {
              height 0.02
              radius 0.03
            }
          }
        ]
        boundingObject USE Wheel
        physics DEF physics_wheel Physics {
        }
        linearVelocity 1.2835432355699545e-11 -2.2031867196151313e-10 -7.221811090419887e-13
        angularVelocity -8.241177062972854e-09 1.0114924478090478e-10 -9.497638631678464e-09
      }
    }
    DEF wheel3 HingeJoint {
      jointParameters HingeJointParameters {
        position 16879.22683824641
        anchor 0.06 0 -0.08
      }
      device [
        RotationalMotor {
          name "wheel3"
          maxVelocity 30
        }
      ]
      endPoint Solid {
        translation 0.0599985522774914 -1.0888207798464232e-05 -0.07998235745278713
        rotation -0.6927189365791847 0.6921677511834322 -0.2025938773168465 3.541681258092272
        children [
          DEF Wheel Shape {
            appearance PBRAppearance {
              baseColor 1 0.4 0.6
              metalness 0
            }
            geometry Cylinder {
              height 0.02
              radius 0.03
            }
          }
        ]
        name "solid(3)"
        boundingObject USE Wheel
        physics DEF physics_wheel Physics {
        }
        linearVelocity 2.1436712229096013e-12 -2.2077554097175381e-10 -1.2336540354687795e-11
        angularVelocity 5.849051509490555e-09 9.683400297578119e-11 6.7378228564643316e-09
      }
    }
    DEF wheel2 HingeJoint {
      jointParameters HingeJointParameters {
        position -12670.43684274545
        anchor -0.06 0 0.08
      }
      device [
        RotationalMotor {
          name "wheel2"
          maxVelocity 30
        }
      ]
      endPoint Solid {
        translation -0.05999912213262848 1.4829773017129094e-05 0.08002377030396957
        rotation -0.6997722444126502 0.6992136181689481 -0.1463527318391098 3.4324651175100485
        children [
          DEF Wheel Shape {
            appearance PBRAppearance {
              baseColor 1 0.4 0.6
              metalness 0
            }
            geometry Cylinder {
              height 0.02
              radius 0.03
            }
          }
        ]
        name "solid(1)"
        boundingObject USE Wheel
        physics DEF physics_wheel Physics {
        }
        linearVelocity 3.3627368250607667e-12 -2.2078672395904098e-10 7.497921186889063e-12
        angularVelocity 6.469878465590522e-09 9.664303067271207e-11 7.453205339429236e-09
      }
    }
    DEF wheel4 HingeJoint {
      jointParameters HingeJointParameters {
        position -14202.390993118162
        anchor -0.06 0 -0.08
      }
      device [
        RotationalMotor {
          name "wheel4"
          maxVelocity 30
        }
      ]
      endPoint Solid {
        translation -0.060000292267891386 -3.0582501657446316e-05 -0.08001608075508079
        rotation -0.6815462902752851 0.6810034221825948 0.2678226898296542 2.6178315481696353
        children [
          DEF Wheel Shape {
            appearance PBRAppearance {
              baseColor 1 0.4 0.6
              metalness 0
            }
            geometry Cylinder {
              height 0.02
              radius 0.03
            }
          }
        ]
        name "solid(2)"
        boundingObject USE Wheel
        physics DEF physics_wheel Physics {
        }
        linearVelocity -7.0185709159699085e-12 -2.2040336110143117e-10 -4.3886307397012484e-12
        angularVelocity -4.72583801902977e-09 1.0007314975275235e-10 -5.447007377824629e-09
      }
    }
    DEF Body Shape {
      appearance PBRAppearance {
        baseColor 0.6 1 0.5
        metalness 0
      }
      geometry Box {
        size 0.1 0.02 0.18
      }
    }
  ]
  boundingObject USE Body
  physics Physics {
    density 2000
    centerOfMass [
      0 0 0
    ]
  }
  controller "ros"
  controllerArgs [
    "--name=ugly_car"
  ]
  linearVelocity 2.779794417654539e-12 -2.2046937115444832e-10 -2.445308569106451e-12
  angularVelocity 1.2610666332880804e-12 9.862521659764487e-11 -2.679520704466206e-13
}
Pedestrian {
  translation -2.05428 1.28 -0.00296715
  rotation 0 1 0 1.5708
  enableBoundingObject TRUE
}
SimpleChair {
  translation 0.42635966624649774 0.9095176688508452 2.25856344470544
  rotation -1.3681558444934616e-07 0.9999999616505404 0.0002769456610768679 3.140604621731949
}
OilBarrel {
  translation -1.69854 0.4398990837379077 2.35572
  rotation 0.9216775286054218 0.387607490829758 -0.016461054536714096 4.207591328708704e-15
  physics Physics {
    density 1
  }
}
DogHouse {
  translation -2.99322 -1.06581e-14 -1.3508
}
