#VRML_SIM R2020b utf8
WorldInfo {
  coordinateSystem "NUE"
  contactProperties [
    ContactProperties {
      coulombFriction [
        0.5
      ]
      forceDependentSlip [
        0.5
      ]
    }
  ]
}
Viewpoint {
  orientation 0.05693550834913929 -0.9889554838129073 -0.1368407794679778 4.1261057820703515
  position 5.021873341679474 2.7394580478758686 6.300513145875758
}
TexturedBackground {
}
TexturedBackgroundLight {
}
Floor {
  size 400 400
  tileSize 6 6
  appearance SandyGround {
  }
}
Pedestrian {
  translation -5.79912 1.28 10.2948
  rotation 0 1 0 1.5708
  name "pedestrian(1)"
  enableBoundingObject TRUE
}
BungalowStyleHouse {
  translation -16.54 0.01 19.91
}
Road {
  translation -43.8 0.01 -9.2
  rotation 0 1 0 1.1781
  width 3
  numberOfLanes 1
  rightBorder FALSE
  leftBorder FALSE
  wayPoints [
    0 0 0
    0 0 100
    200 0 200
  ]
  splineSubdivision 8
  appearance Pavement {
    type "black stone"
  }
}
PottedTree {
  translation -1.7314739335631057 -0.00774529672103641 7.883765177781367
  rotation 2.0861696133151117e-12 1 1.0412277246916275e-13 1.432604479377318e-05
  name "potted tree(1)"
  physics Physics {
    density 50
  }
}
Toilet {
  translation -0.473119 0 14.5756
  rotation 0 1 0 -1.5707953071795862
}
WoodenBox {
  translation -7.951020036436661 0.44215200030871815 13.368845543980777
  rotation 0.9999999841910913 -1.840431275028385e-13 0.0001778139971889655 -3.141592647545013
  name "wooden box(5)"
  size 0.3 0.9 0.3
  mass 20
}
Desk {
  translation -6.25435 0 7.26169
}
WoodenBox {
  translation -2.455024157919319 0.1421520003087179 14.617767759284686
  rotation -3.98889467744141e-17 1 -5.37452553971524e-16 0.2068028733133174
  size 0.3 0.3 0.3
  mass 20
}
WoodenBox {
  translation -4.015183227237557 0.2921520003087179 8.892511291214834
  rotation -4.26399479037255e-15 1 4.410928569627426e-17 0.03586899590639884
  name "wooden box(1)"
  size 0.3 0.6 0.3
  mass 20
}
WoodenBox {
  translation -4.4812438674639745 0.44215200030871793 10.376567187137246
  rotation 8.233977662775024e-17 1 -1.347631278750805e-16 1.8076656816995575
  name "wooden box(4)"
  size 0.3 0.9 0.3
  mass 20
}
WoodenBox {
  translation -6.074104255715686 0.1421520003087179 1.705599713530807
  rotation 2.130864123315332e-14 1 -7.618249213040373e-14 0.004381297743619868
  name "wooden box(2)"
  size 0.3 0.3 0.3
  mass 20
}
WoodenBox {
  translation 1.0395264719140889 0.1421520003087179 13.290771641187458
  rotation 4.534261363967839e-18 1 -5.811195207763208e-18 1.1035383614606449
  name "wooden box(3)"
  size 0.3 0.3 0.3
  mass 20
}
Robot {
  translation -2.3350385733286956 0.029822962369762614 10.975436866299862
  rotation 0.00010315496933330886 -0.9999999940092202 3.6614367601212476e-05 -2.8035817391264417
  children [
    Camera {
      translation 0 0.016 0.085
      rotation 0 1 0 3.14
      children [
        Transform {
          rotation 0 1 0 3.14
          children [
            Shape {
              appearance PBRAppearance {
                baseColor 0.5 0 1
                metalness 0
              }
              geometry Cone {
                bottomRadius 0.005
                height 0.01
              }
            }
          ]
        }
      ]
      fieldOfView 2
      width 256
      height 128
    }
    GPS {
    }
    Compass {
      translation -0.02 0.01 0
      children [
        Shape {
          appearance PBRAppearance {
            baseColor 0 0.2 1
            metalness 0
          }
          geometry Cylinder {
            height 0.005
            radius 0.01
          }
        }
      ]
    }
    Accelerometer {
      translation 0.02 0.01 0
      children [
        Shape {
          appearance PBRAppearance {
            baseColor 0 0.2 1
            metalness 0
          }
          geometry Cylinder {
            height 0.005
            radius 0.01
          }
        }
      ]
    }
    Gyro {
      translation 0 0.01 0.02
      children [
        Shape {
          appearance PBRAppearance {
            baseColor 1 0.1 0.1
            metalness 0
          }
          geometry Box {
            size 0.05 0.005 0.015
          }
        }
      ]
    }
    InertialUnit {
      translation 0 0.01 0.02
      children [
        Shape {
          appearance PBRAppearance {
            baseColor 1 0.1 0.1
            metalness 0
          }
          geometry Box {
            size 0.015 0.005 0.04
          }
        }
      ]
      name "imu"
    }
    DistanceSensor {
      translation 0.03 0 0.097
      rotation 0 1 0 -1.57
      children [
        Shape {
          appearance PBRAppearance {
            baseColor 0.2 1 1
            metalness 0
          }
          geometry Box {
            size 0.015 0.015 0.015
          }
        }
      ]
      name "ds_left"
    }
    DistanceSensor {
      translation -0.03 0 0.097
      rotation 0 1 0 -1.57
      children [
        Shape {
          appearance PBRAppearance {
            baseColor 0.2 1 1
            metalness 0
          }
          geometry Box {
            size 0.015 0.015 0.015
          }
        }
      ]
      name "ds_right"
    }
    DEF lidar Transform {
      translation 0 0.07 -0.04
      rotation 0 1 0 3.14
      children [
        Shape {
          appearance PBRAppearance {
            metalness 0
          }
          geometry Box {
            size 0.03 0.03 0.03
          }
        }
        DEF LIDAR Lidar {
          name "sick"
          model "sick_model"
          horizontalResolution 1200
          fieldOfView 6.283
          verticalFieldOfView 0.785
          numberOfLayers 64
          minRange 0.1
          maxRange 100
          defaultFrequency 30
          maxFrequency 30
        }
      ]
    }
    DEF wheel1 HingeJoint {
      jointParameters HingeJointParameters {
        position 17067.193481038223
        anchor 0.06 0 0.08
      }
      device [
        RotationalMotor {
          name "wheel1"
          maxVelocity 30
        }
      ]
      endPoint Solid {
        translation 0.06000388540791468 4.56149707035197e-06 0.0800457323250197
        rotation -0.6492459499437189 0.6487299806249492 -0.3970253250361125 3.898018660972912
        children [
          DEF Wheel Shape {
            appearance PBRAppearance {
              baseColor 1 0.4 0.6
              metalness 0
            }
            geometry Cylinder {
              height 0.02
              radius 0.03
            }
          }
        ]
        boundingObject USE Wheel
        physics DEF physics_wheel Physics {
        }
        linearVelocity -4.8103817154727725e-12 9.423925971857516e-15 3.987416943837483e-12
        angularVelocity 7.382326683904375e-10 4.0259486205762146e-11 2.595816210890487e-10
      }
    }
    DEF wheel3 HingeJoint {
      jointParameters HingeJointParameters {
        position 17054.93699968367
        anchor 0.06 0 -0.08
      }
      device [
        RotationalMotor {
          name "wheel3"
          maxVelocity 30
        }
      ]
      endPoint Solid {
        translation 0.0599985522774914 -6.794705795017156e-06 -0.07998041315455771
        rotation -0.6786532497550124 0.6781133621018872 -0.2821206031750171 3.691958710706566
        children [
          DEF Wheel Shape {
            appearance PBRAppearance {
              baseColor 1 0.4 0.6
              metalness 0
            }
            geometry Cylinder {
              height 0.02
              radius 0.03
            }
          }
        ]
        name "solid(3)"
        boundingObject USE Wheel
        physics DEF physics_wheel Physics {
        }
        linearVelocity 1.2422841760276199e-12 -8.481547064168645e-15 6.140013626299298e-12
        angularVelocity 3.439527090420821e-10 4.017170348490179e-11 1.2103206244538946e-10
      }
    }
    DEF wheel2 HingeJoint {
      jointParameters HingeJointParameters {
        position -12593.347725285566
        anchor -0.06 0 0.08
      }
      device [
        RotationalMotor {
          name "wheel2"
          maxVelocity 30
        }
      ]
      endPoint Solid {
        translation -0.05999912213262848 -2.537582522784029e-05 0.08001187505842307
        rotation -0.6262463414373889 0.6257458133505216 0.4650351566393443 2.2704095097315546
        children [
          DEF Wheel Shape {
            appearance PBRAppearance {
              baseColor 1 0.4 0.6
              metalness 0
            }
            geometry Cylinder {
              height 0.02
              radius 0.03
            }
          }
        ]
        name "solid(1)"
        boundingObject USE Wheel
        physics DEF physics_wheel Physics {
        }
        linearVelocity -3.2096002019173115e-12 -1.0491943642481493e-14 -5.295502799992463e-13
        angularVelocity 2.3013291318463755e-10 4.014464198443146e-11 8.101399554331486e-11
      }
    }
    DEF wheel4 HingeJoint {
      jointParameters HingeJointParameters {
        position -14126.58176231625
        anchor -0.06 0 -0.08
      }
      device [
        RotationalMotor {
          name "wheel4"
          maxVelocity 30
        }
      ]
      endPoint Solid {
        translation -0.060000292267891386 -2.1610768985374108e-05 -0.08002696024397991
        rotation -0.6418510729499911 0.641339822946557 0.42036939904781856 2.345139250310448
        children [
          DEF Wheel Shape {
            appearance PBRAppearance {
              baseColor 1 0.4 0.6
              metalness 0
            }
            geometry Cylinder {
              height 0.02
              radius 0.03
            }
          }
        ]
        name "solid(2)"
        boundingObject USE Wheel
        physics DEF physics_wheel Physics {
        }
        linearVelocity 2.8383747179974032e-12 8.732771381450994e-15 1.5904054346410306e-12
        angularVelocity -4.1443849368385073e-10 3.999892104233753e-11 -1.4555184837649817e-10
      }
    }
    DEF Body Shape {
      appearance PBRAppearance {
        baseColor 0.6 1 0.5
        metalness 0
      }
      geometry Box {
        size 0.1 0.02 0.18
      }
    }
  ]
  boundingObject USE Body
  physics Physics {
    density 2000
    centerOfMass [
      0 0 0
    ]
  }
  controller "ros"
  controllerArgs [
    "--name=ugly_car"
  ]
  linearVelocity -9.856571706947239e-13 -1.452665148665094e-14 2.7978953265195055e-12
  angularVelocity -9.597489672594724e-14 4.009260174140435e-11 7.571006148670673e-14
}
Pedestrian {
  translation 0.101333 1.28 10.9383
  rotation 0 1 0 1.5708
  enableBoundingObject TRUE
}
SimpleChair {
  translation -3.277010686272789 0.2870903493704488 12.693246247341845
  rotation 0.24162784943525012 0.6935393598499948 0.6786892799478679 -2.6574469756813555
}
OilBarrel {
  translation -5.505557238432563 0.43989908373482783 14.392910284285467
  rotation 1.9957423055842978e-12 1 1.2479173232045607e-12 1.6923180790548517e-05
  physics Physics {
    density 1
  }
}
OilBarrel {
  translation -5.62398973602436 0.43989908373482794 17.62990934145798
  rotation -4.5223936510775e-16 1 4.0367384368701824e-16 -0.02642720767081546
  name "oil barrel(1)"
  physics Physics {
    density 1
  }
}
DogHouse {
  translation -3.1254 -1.06581e-14 17.4974
}
Forest {
  translation 70 0 28
  shape [
    200 200
    200 0
    50 0
    50 50
    -50 50
    -50 -50
    50 -50
    50 0
    200 0
    200 -200
    -200 -200
    -200 200
  ]
  density 0.01
  type "cherry tree"
  randomSeed 1
  maxHeight 8
  minHeight 6
  minRadius 3
}
